Workbook

Sheet Resumen
B2: PLASTIR SRL | Liquidación de mercancías
B5: Referencia de la operación | E5: A26TM06007 | 4 facturas | Ningbo a Caucedo
B6: Proveedor | E6: NINGBO TOPWIN CO., LTD
B7: Término comercial | E7: FOB | transporte marítimo
B8: Consignatario en facturas | E8: JLG CARGO SRL | validar vínculo con PLASTIR SRL
B9: Tasa USD / RD$ | E9: =IF('Facturas y gastos'!B5="","",'Facturas y gastos'!B5)
B10: Estado de liquidación | E10: =IF('Facturas y gastos'!B5="","PENDIENTE TASA USD/RD$",IF('Facturas y gastos'!B24="","PENDIENTE ARANCEL DUA",IF('Facturas y gastos'!B45<>"OK",'Facturas y gastos'!B45,IF(OR('Facturas y gastos'!P10="REVISAR",'Facturas y gastos'!P11="REVISAR",'Facturas y gastos'!P12="REVISAR",'Facturas y gastos'!P13="REVISAR"),"REVISAR DIFERENCIAS PDF","LISTA PARA REVISIÓN")))) -> PENDIENTE TASA USD/RD$
B12: COMPONENTES DE COSTO
B14: Mercancía FOB según facturas USD | H14: =SUM('Facturas y gastos'!D10:D13) -> 169772.96
B15: Descuentos del proveedor USD | H15: =SUM('Facturas y gastos'!G10:G13) -> 1697.73
B16: Comisión según facturas USD | H16: =SUM('Facturas y gastos'!H10:H13) -> 5093.18
B17: Flete internacional USD | H17: =SUM('Facturas y gastos'!I10:I13) -> 31600
B18: Seguro internacional USD | H18: =SUM('Facturas y gastos'!J10:J13) -> 0
B19: Costo factura liquidado USD | H19: =H14-H15+H16+H17+H18 -> 204768.41
B21: Costo convertido RD$ | H21: =IF('Facturas y gastos'!B5="","",H19*'Facturas y gastos'!B5)
B22: Gastos y tributos capitalizables RD$ | H22: =IF('Facturas y gastos'!B24="","",'Facturas y gastos'!B43)
B23: COSTO TOTAL INVENTARIO RD$ | H23: =IF(OR(H21="",H22="",'Facturas y gastos'!B45<>"OK"),"",H21+H22)
B24: Costo promedio por unidad RD$ | H24: =IF(OR(H23="",SUM('Facturas y gastos'!O10:O13)=0),"",H23/SUM('Facturas y gastos'!O10:O13))
B26: ITBIS pagado RD$ | H26: =IF('Facturas y gastos'!B39="","",'Facturas y gastos'!B39)
B27: ITBIS recuperable RD$ | H27: =IF('Facturas y gastos'!B40="","",'Facturas y gastos'!B40)
B30: RECONCILIACIÓN DOCUMENTAL
B32: Facturas | H32: =COUNTA('Facturas y gastos'!A10:A13) -> 4
B33: Renglones de artículos | H33: =COUNTA(Mercancias!C8:C657) -> 506
B34: Unidades según facturas | H34: =SUM('Facturas y gastos'!O10:O13) -> 123552
B35: Cajas según facturas | H35: =SUM('Facturas y gastos'!N10:N13) -> 2880
B36: Diferencia líneas vs. subtotales USD | H36: =SUM('Facturas y gastos'!F10:F13) -> 0.08
B37: Diferencia de cierre de facturas USD | H37: =SUM('Facturas y gastos'!M10:M13) -> -0.01
B39: Nota de revisión | E39: Las facturas nombran a JLG CARGO SRL; validar soporte de PLASTIR.
E40: El prorrateo corrige los centavos con el subtotal FOB impreso.
E41: Prorrateo de arancel por valor; ajustar si DUA diferencia partidas.
B42: Control distribución USD | H42: =ROUND(SUM(Mercancias!O8:O657)-H19,2) -> 0
B43: Control distribución RD$ | H43: =IF(H23="","",ROUND(SUM(Mercancias!Q8:Q657)-H23,2))

Sheet Facturas y gastos
A2: Facturas, controles y gastos de importación
A4: Operación | B4: A26TM06007
A5: Tasa USD / RD$ | D5: Ingrese la tasa efectiva usada para la liquidación.
A7: Facturas del proveedor | campos amarillos: editar / completar
A9: Factura | B9: Fecha | C9: Destinatario | D9: FOB PDF USD | E9: Detalle USD | F9: Diferencia USD | G9: Descuento USD | H9: Comisión USD | I9: Flete USD | J9: Seguro USD | K9: Total calculado USD | L9: Total PDF USD | M9: Diferencia total | N9: Cajas | O9: Unidades | P9: Control
A10: A26TM06007-1 | B10: 46231 | C10: JLG CARGO SRL | D10: 45174.76 | E10: =SUMIFS(Mercancias!$I$8:$I$657,Mercancias!$A$8:$A$657,A10) -> 45174.76 | F10: =E10-D10 -> 0 | G10: 451.75 | H10: 1355.24 | I10: 7900 | K10: =D10-G10+H10+I10+J10 -> 53978.25 | L10: 53978.26 | M10: =K10-L10 -> -0.01 | N10: 614 | O10: 24114 | P10: =IF(OR(ABS(F10)>0.015,ABS(M10)>0.015),"REVISAR","OK") -> OK
A11: A26TM06007-2 | B11: 46231 | C11: JLG CARGO SRL | D11: 39046.73 | E11: =SUMIFS(Mercancias!$I$8:$I$657,Mercancias!$A$8:$A$657,A11) -> 39046.81 | F11: =E11-D11 -> 0.08 | G11: 390.47 | H11: 1171.4 | I11: 7900 | K11: =D11-G11+H11+I11+J11 -> 47727.66 | L11: 47727.67 | M11: =K11-L11 -> -0.01 | N11: 922 | O11: 40682 | P11: =IF(OR(ABS(F11)>0.015,ABS(M11)>0.015),"REVISAR","OK") -> REVISAR
A12: A26TM06007-3 | B12: 46231 | C12: JLG CARGO SRL | D12: 39784.34 | E12: =SUMIFS(Mercancias!$I$8:$I$657,Mercancias!$A$8:$A$657,A12) -> 39784.35 | F12: =E12-D12 -> 0.01 | G12: 397.84 | H12: 1193.53 | I12: 7900 | K12: =D12-G12+H12+I12+J12 -> 48480.03 | L12: 48480.02 | M12: =K12-L12 -> 0.01 | N12: 823 | O12: 30780 | P12: =IF(OR(ABS(F12)>0.015,ABS(M12)>0.015),"REVISAR","OK") -> OK
A13: A26TM06007-4 | B13: 46231 | C13: JLG CARGO SRL | D13: 45767.13 | E13: =SUMIFS(Mercancias!$I$8:$I$657,Mercancias!$A$8:$A$657,A13) -> 45767.12 | F13: =E13-D13 -> -0.01 | G13: 457.67 | H13: 1373.01 | I13: 7900 | K13: =D13-G13+H13+I13+J13 -> 54582.47 | L13: 54582.47 | M13: =K13-L13 -> 0 | N13: 521 | O13: 27976 | P13: =IF(OR(ABS(F13)>0.015,ABS(M13)>0.015),"REVISAR","OK") -> OK
A15: Total operación | D15: =SUM(D10:D13) -> 169772.96 | E15: =SUM(E10:E13) -> 169773.04 | F15: =SUM(F10:F13) -> 0.08 | G15: =SUM(G10:G13) -> 1697.73 | H15: =SUM(H10:H13) -> 5093.18 | I15: =SUM(I10:I13) -> 31600 | J15: =SUM(J10:J13) -> 0 | K15: =SUM(K10:K13) -> 204768.41 | ... O15: =SUM(O10:O13) -> 123552
A18: Fuente: NINGBO TOPWIN CO., LTD, facturas A26TM06007-1 a -4, fechadas 28/07/2026, PDF adjunto, páginas de INVOICE.
A19: Los subtotales oficiales prevalecen para distribuir centavos: diferencia detalle y diferencias del cierre quedan visibles.
A21: Gastos pagados en RD$ | documentar valores reales
A22: Concepto | B22: Valor RD$ | C22: Soporte / número | D22: Tratamiento
A24: Arancel aduanero | D24: Costo inventario
A25: Impuesto selectivo al consumo | D25: Costo inventario
A26: Tasas y servicios portuarios | D26: Costo inventario
A27: Agente aduanal y despacho | D27: Costo inventario
A28: Transporte local a almacén | D28: Costo inventario
A29: Almacenaje antes de disponibilidad | D29: Costo inventario
A30: Inspección y manipulación | D30: Costo inventario
A31: Otros gastos atribuibles 1 | D31: Costo inventario
A32: Otros gastos atribuibles 2 | D32: Costo inventario
A34: Subtotal otros gastos y tributos | B34: =SUM(B24:B32) -> 0
A39: ITBIS pagado | valor DUA
A40: ITBIS recuperable | crédito fiscal
A41: ITBIS no recuperable | costo | B41: =IF(AND(B39="",B40=""),"",MAX(0,N(B39)-N(B40)))
A43: GASTOS CAPITALIZABLES RD$ | B43: =B34+N(B41) -> 0
A45: Control ITBIS | B45: =IF(OR(B39="",B40=""),"PENDIENTE ITBIS",IF(B40>B39,"REVISAR RECUPERABLE","OK")) -> PENDIENTE ITBIS
A47: Guía
A48: Registrar costos nacionales sin duplicar comisión, flete y seguro ya incluidos arriba.
A49: Capturar ITBIS recuperable solo con derecho a crédito; el saldo no recuperable integra el inventario.
A50: Si un gasto no corresponde al inventario, registrarlo fuera de esta plantilla.

Sheet Mercancias
A2: Mercancías | costo por artículo
A3: Fuente: facturas y listas de empaque NINGBO TOPWIN CO., LTD, A26TM06007-1 a -4, PDF adjunto (46 páginas).
A4: Valor USD de cada línea: total impreso; precio unitario mostrado puede estar redondeado.
A5: Distribución: FOB según subtotal impreso; luego descuento, comisión, flete, seguro y gastos RD$ proporcionales al valor por factura.
A7: Factura | B7: Núm. | C7: Código SKU | D7: Descripción | E7: Unidad | F7: Unidades | G7: Cajas | H7: Precio ref. USD | I7: Importe PDF USD | J7: FOB conciliado USD | K7: Descuento USD | L7: Comisión USD | M7: Flete USD | N7: Seguro USD | O7: Costo puesto USD | P7: Gastos RD$ | Q7: Costo total RD$ | R7: Unitario RD$
A8: A26TM06007-1 | B8: 1 | C8: PG153 | D8: Imán de nevera | E8: PCS | F8: 2400 | G8: 5 | H8: 0.25 | I8: 591.04 | J8: =IF(OR(A8="",I8=""),"",IF(SUMIFS($I$8:$I$657,$A$8:$A$657,A8)=0,"",I8*SUMIFS('Facturas y gastos'!$D$10:$D$13,'Facturas y gastos'!$A$10:$A$13,A8)/SUMIFS($I$8:$I$657,$A$8:$A$657,A8))) -> 591.04 | K8: =IF(J8="","",IF(SUMIFS('Facturas y gastos'!$D$10:$D$13,'Facturas y gastos'!$A$10:$A$13,A8)=0,"",J8*SUMIFS('Facturas y gastos'!$G$10:$G$13,'Facturas y gastos'!$A$10:$A$13,A8)/SUMIFS('Facturas y gastos'!$D$10:$D$13,'Facturas y gastos'!$A$10:$A$13,A8))) -> 5.9104314 | L8: =IF(J8="","",IF(SUMIFS('Facturas y gastos'!$D$10:$D$13,'Facturas y gastos'!$A$10:$A$13,A8)=0,"",J8*SUMIFS('Facturas y gastos'!$H$10:$H$13,'Facturas y gastos'!$A$10:$A$13,A8)/SUMIFS('Facturas y gastos'!$D$10:$D$13,'Facturas y gastos'!$A$10:$A$13,A8))) -> 17.731163 | M8: =IF(J8="","",IF(SUMIFS('Facturas y gastos'!$D$10:$D$13,'Facturas y gastos'!$A$10:$A$13,A8)=0,"",J8*SUMIFS('Facturas y gastos'!$I$10:$I$13,'Facturas y gastos'!$A$10:$A$13,A8)/SUMIFS('Facturas y gastos'!$D$10:$D$13,'Facturas y gastos'!$A$10:$A$13,A8))) -> 103.35896 | N8: =IF(J8="","",IF(SUMIFS('Facturas y gastos'!$D$10:$D$13,'Facturas y gastos'!$A$10:$A$13,A8)=0,"",J8*SUMIFS('Facturas y gastos'!$J$10:$J$13,'Facturas y gastos'!$A$10:$A$13,A8)/SUMIFS('Facturas y gastos'!$D$10:$D$13,'Facturas y gastos'!$A$10:$A$13,A8))) -> 0 | O8: =IF(J8="","",J8-K8+L8+M8+N8) -> 706.21969 | P8: =IF(OR(O8="",'Facturas y gastos'!$B$24="",'Facturas y gastos'!$B$45<>"OK",SUM($O$8:$O$657)=0),"",O8*'Facturas y gastos'!$B$43/SUM($O$8:$O$657)) | Q8: =IF(OR(O8="",'Facturas y gastos'!$B$5="",P8=""),"",O8*'Facturas y gastos'!$B$5+P8) | R8: =IF(OR(Q8="",F8="",F8=0),"",Q8/F8)
A9: A26TM06007-1 | B9: 2 | C9: PG154 | D9: Imán de nevera | E9: PCS | F9: 2400 | G9: 5 | H9: 0.2 | I9: 483.58 | J9: =IF(OR(A9="",I9=""),"",IF(SUMIFS($I$8:$I$657,$A$8:$A$657,A9)=0,"",I9*SUMIFS('Facturas y gastos'!$D$10:$D$13,'Facturas y gastos'!$A$10:$A$13,A9)/SUMIFS($I$8:$I$657,$A$8:$A$657,A9))) -> 483.58 | K9: =IF(J9="","",IF(SUMIFS('Facturas y gastos'!$D$10:$D$13,'Facturas y gastos'!$A$10:$A$13,A9)=0,"",J9*SUMIFS('Facturas y gastos'!$G$10:$G$13,'Facturas y gastos'!$A$10:$A$13,A9)/SUMIFS('Facturas y gastos'!$D$10:$D$13,'Facturas y gastos'!$A$10:$A$13,A9))) -> 4.8358257 | L9: =IF(J9="","",IF(SUMIFS('Facturas y gastos'!$D$10:$D$13,'Facturas y gastos'!$A$10:$A$13,A9)=0,"",J9*SUMIFS('Facturas y gastos'!$H$10:$H$13,'Facturas y gastos'!$A$10:$A$13,A9)/SUMIFS('Facturas y gastos'!$D$10:$D$13,'Facturas y gastos'!$A$10:$A$13,A9))) -> 14.50737 | M9: =IF(J9="","",IF(SUMIFS('Facturas y gastos'!$D$10:$D$13,'Facturas y gastos'!$A$10:$A$13,A9)=0,"",J9*SUMIFS('Facturas y gastos'!$I$10:$I$13,'Facturas y gastos'!$A$10:$A$13,A9)/SUMIFS('Facturas y gastos'!$D$10:$D$13,'Facturas y gastos'!$A$10:$A$13,A9))) -> 84.566736 | N9: =IF(J9="","",IF(SUMIFS('Facturas y gastos'!$D$10:$D$13,'Facturas y gastos'!$A$10:$A$13,A9)=0,"",J9*SUMIFS('Facturas y gastos'!$J$10:$J$13,'Facturas y gastos'!$A$10:$A$13,A9)/SUMIFS('Facturas y gastos'!$D$10:$D$13,'Facturas y gastos'!$A$10:$A$13,A9))) -> 0 | O9: =IF(J9="","",J9-K9+L9+M9+N9) -> 577.81828 | P9: =IF(OR(O9="",'Facturas y gastos'!$B$24="",'Facturas y gastos'!$B$45<>"OK",SUM($O$8:$O$657)=0),"",O9*'Facturas y gastos'!$B$43/SUM($O$8:$O$657)) | Q9: =IF(OR(O9="",'Facturas y gastos'!$B$5="",P9=""),"",O9*'Facturas y gastos'!$B$5+P9) | R9: =IF(OR(Q9="",F9="",F9=0),"",Q9/F9)
A10: A26TM06007-1 | B10: 3 | C10: PG155 | D10: Imán de nevera | E10: PCS | F10: 2400 | G10: 5 | H10: 0.19 | I10: 447.76 | J10: =IF(OR(A10="",I10=""),"",IF(SUMIFS($I$8:$I$657,$A$8:$A$657,A10)=0,"",I10*SUMIFS('Facturas y gastos'!$D$10:$D$13,'Facturas y gastos'!$A$10:$A$13,A10)/SUMIFS($I$8:$I$657,$A$8:$A$657,A10))) -> 447.76 | K10: =IF(J10="","",IF(SUMIFS('Facturas y gastos'!$D$10:$D$13,'Facturas y gastos'!$A$10:$A$13,A10)=0,"",J10*SUMIFS('Facturas y gastos'!$G$10:$G$13,'Facturas y gastos'!$A$10:$A$13,A10)/SUMIFS('Facturas y gastos'!$D$10:$D$13,'Facturas y gastos'!$A$10:$A$13,A10))) -> 4.4776238 | L10: =IF(J10="","",IF(SUMIFS('Facturas y gastos'!$D$10:$D$13,'Facturas y gastos'!$A$10:$A$13,A10)=0,"",J10*SUMIFS('Facturas y gastos'!$H$10:$H$13,'Facturas y gastos'!$A$10:$A$13,A10)/SUMIFS('Facturas y gastos'!$D$10:$D$13,'Facturas y gastos'!$A$10:$A$13,A10))) -> 13.432772 | M10: =IF(J10="","",IF(SUMIFS('Facturas y gastos'!$D$10:$D$13,'Facturas y gastos'!$A$10:$A$13,A10)=0,"",J10*SUMIFS('Facturas y gastos'!$I$10:$I$13,'Facturas y gastos'!$A$10:$A$13,A10)/SUMIFS('Facturas y gastos'!$D$10:$D$13,'Facturas y gastos'!$A$10:$A$13,A10))) -> 78.302663 | N10: =IF(J10="","",IF(SUMIFS('Facturas y gastos'!$D$10:$D$13,'Facturas y gastos'!$A$10:$A$13,A10)=0,"",J10*SUMIFS('Facturas y gastos'!$J$10:$J$13,'Facturas y gastos'!$A$10:$A$13,A10)/SUMIFS('Facturas y gastos'!$D$10:$D$13,'Facturas y gastos'!$A$10:$A$13,A10))) -> 0 | O10: =IF(J10="","",J10-K10+L10+M10+N10) -> 535.01781 | P10: =IF(OR(O10="",'Facturas y gastos'!$B$24="",'Facturas y gastos'!$B$45<>"OK",SUM($O$8:$O$657)=0),"",O10*'Facturas y gastos'!$B$43/SUM($O$8:$O$657)) | Q10: =IF(OR(O10="",'Facturas y gastos'!$B$5="",P10=""),"",O10*'Facturas y gastos'!$B$5+P10) | R10: =IF(OR(Q10="",F10="",F10=0),"",Q10/F10)
A11: A26TM06007-1 | B11: 4 | C11: PG283 | D11: set de taza | E11: PCS | F11: 180 | G11: 5 | H11: 2.02 | I11: 363.6 | J11: =IF(OR(A11="",I11=""),"",IF(SUMIFS($I$8:$I$657,$A$8:$A$657,A11)=0,"",I11*SUMIFS('Facturas y gastos'!$D$10:$D$13,'Facturas y gastos'!$A$10:$A$13,A11)/SUMIFS($I$8:$I$657,$A$8:$A$657,A11))) -> 363.6 | K11: =IF(J11="","",IF(SUMIFS('Facturas y gastos'!$D$10:$D$13,'Facturas y gastos'!$A$10:$A$13,A11)=0,"",J11*SUMIFS('Facturas y gastos'!$G$10:$G$13,'Facturas y gastos'!$A$10:$A$13,A11)/SUMIFS('Facturas y gastos'!$D$10:$D$13,'Facturas y gastos'!$A$10:$A$13,A11))) -> 3.6360193 | L11: =IF(J11="","",IF(SUMIFS('Facturas y gastos'!$D$10:$D$13,'Facturas y gastos'!$A$10:$A$13,A11)=0,"",J11*SUMIFS('Facturas y gastos'!$H$10:$H$13,'Facturas y gastos'!$A$10:$A$13,A11)/SUMIFS('Facturas y gastos'!$D$10:$D$13,'Facturas y gastos'!$A$10:$A$13,A11))) -> 10.907977 | M11: =IF(J11="","",IF(SUMIFS('Facturas y gastos'!$D$10:$D$13,'Facturas y gastos'!$A$10:$A$13,A11)=0,"",J11*SUMIFS('Facturas y gastos'!$I$10:$I$13,'Facturas y gastos'!$A$10:$A$13,A11)/SUMIFS('Facturas y gastos'!$D$10:$D$13,'Facturas y gastos'!$A$10:$A$13,A11))) -> 63.585064 | N11: =IF(J11="","",IF(SUMIFS('Facturas y gastos'!$D$10:$D$13,'Facturas y gastos'!$A$10:$A$13,A11)=0,"",J11*SUMIFS('Facturas y gastos'!$J$10:$J$13,'Facturas y gastos'!$A$10:$A$13,A11)/SUMIFS('Facturas y gastos'!$D$10:$D$13,'Facturas y gastos'!$A$10:$A$13,A11))) -> 0 | O11: =IF(J11="","",J11-K11+L11+M11+N11) -> 434.45702 | P11: =IF(OR(O11="",'Facturas y gastos'!$B$24="",'Facturas y gastos'!$B$45<>"OK",SUM($O$8:$O$657)=0),"",O11*'Facturas y gastos'!$B$43/SUM($O$8:$O$657)) | Q11: =IF(OR(O11="",'Facturas y gastos'!$B$5="",P11=""),"",O11*'Facturas y gastos'!$B$5+P11) | R11: =IF(OR(Q11="",F11="",F11=0),"",Q11/F11)
A12: A26TM06007-1 | B12: 5 | C12: PG284 | D12: set de taza | E12: PCS | F12: 300 | G12: 5 | H12: 1.1 | I12: 330 | J12: =IF(OR(A12="",I12=""),"",IF(SUMIFS($I$8:$I$657,$A$8:$A$657,A12)=0,"",I12*SUMIFS('Facturas y gastos'!$D$10:$D$13,'Facturas y gastos'!$A$10:$A$13,A12)/SUMIFS($I$8:$I$657,$A$8:$A$657,A12))) -> 330 | K12: =IF(J12="","",IF(SUMIFS('Facturas y gastos'!$D$10:$D$13,'Facturas y gastos'!$A$10:$A$13,A12)=0,"",J12*SUMIFS('Facturas y gastos'!$G$10:$G$13,'Facturas y gastos'!$A$10:$A$13,A12)/SUMIFS('Facturas y gastos'!$D$10:$D$13,'Facturas y gastos'!$A$10:$A$13,A12))) -> 3.3000175 | L12: =IF(J12="","",IF(SUMIFS('Facturas y gastos'!$D$10:$D$13,'Facturas y gastos'!$A$10:$A$13,A12)=0,"",J12*SUMIFS('Facturas y gastos'!$H$10:$H$13,'Facturas y gastos'!$A$10:$A$13,A12)/SUMIFS('Facturas y gastos'!$D$10:$D$13,'Facturas y gastos'!$A$10:$A$13,A12))) -> 9.8999795 | M12: =IF(J12="","",IF(SUMIFS('Facturas y gastos'!$D$10:$D$13,'Facturas y gastos'!$A$10:$A$13,A12)=0,"",J12*SUMIFS('Facturas y gastos'!$I$10:$I$13,'Facturas y gastos'!$A$10:$A$13,A12)/SUMIFS('Facturas y gastos'!$D$10:$D$13,'Facturas y gastos'!$A$10:$A$13,A12))) -> 57.709216 | N12: =IF(J12="","",IF(SUMIFS('Facturas y gastos'!$D$10:$D$13,'Facturas y gastos'!$A$10:$A$13,A12)=0,"",J12*SUMIFS('Facturas y gastos'!$J$10:$J$13,'Facturas y gastos'!$A$10:$A$13,A12)/SUMIFS('Facturas y gastos'!$D$10:$D$13,'Facturas y gastos'!$A$10:$A$13,A12))) -> 0 | O12: =IF(J12="","",J12-K12+L12+M12+N12) -> 394.30918 | P12: =IF(OR(O12="",'Facturas y gastos'!$B$24="",'Facturas y gastos'!$B$45<>"OK",SUM($O$8:$O$657)=0),"",O12*'Facturas y gastos'!$B$43/SUM($O$8:$O$657)) | Q12: =IF(OR(O12="",'Facturas y gastos'!$B$5="",P12=""),"",O12*'Facturas y gastos'!$B$5+P12) | R12: =IF(OR(Q12="",F12="",F12=0),"",Q12/F12)
A13: A26TM06007-1 | B13: 6 | C13: PG286 | D13: set de taza | E13: PCS | F13: 300 | G13: 5 | H13: 1.1 | I13: 330 | J13: =IF(OR(A13="",I13=""),"",IF(SUMIFS($I$8:$I$657,$A$8:$A$657,A13)=0,"",I13*SUMIFS('Facturas y gastos'!$D$10:$D$13,'Facturas y gastos'!$A$10:$A$13,A13)/SUMIFS($I$8:$I$657,$A$8:$A$657,A13))) -> 330 | K13: =IF(J13="","",IF(SUMIFS('Facturas y gastos'!$D$10:$D$13,'Facturas y gastos'!$A$10:$A$13,A13)=0,"",J13*SUMIFS('Facturas y gastos'!$G$10:$G$13,'Facturas y gastos'!$A$10:$A$13,A13)/SUMIFS('Facturas y gastos'!$D$10:$D$13,'Facturas y gastos'!$A$10:$A$13,A13))) -> 3.3000175 | L13: =IF(J13="","",IF(SUMIFS('Facturas y gastos'!$D$10:$D$13,'Facturas y gastos'!$A$10:$A$13,A13)=0,"",J13*SUMIFS('Facturas y gastos'!$H$10:$H$13,'Facturas y gastos'!$A$10:$A$13,A13)/SUMIFS('Facturas y gastos'!$D$10:$D$13,'Facturas y gastos'!$A$10:$A$13,A13))) -> 9.8999795 | M13: =IF(J13="","",IF(SUMIFS('Facturas y gastos'!$D$10:$D$13,'Facturas y gastos'!$A$10:$A$13,A13)=0,"",J13*SUMIFS('Facturas y gastos'!$I$10:$I$13,'Facturas y gastos'!$A$10:$A$13,A13)/SUMIFS('Facturas y gastos'!$D$10:$D$13,'Facturas y gastos'!$A$10:$A$13,A13))) -> 57.709216 | N13: =IF(J13="","",IF(SUMIFS('Facturas y gastos'!$D$10:$D$13,'Facturas y gastos'!$A$10:$A$13,A13)=0,"",J13*SUMIFS('Facturas y gastos'!$J$10:$J$13,'Facturas y gastos'!$A$10:$A$13,A13)/SUMIFS('Facturas y gastos'!$D$10:$D$13,'Facturas y gastos'!$A$10:$A$13,A13))) -> 0 | O13: =IF(J13="","",J13-K13+L13+M13+N13) -> 394.30918 | P13: =IF(OR(O13="",'Facturas y gastos'!$B$24="",'Facturas y gastos'!$B$45<>"OK",SUM($O$8:$O$657)=0),"",O13*'Facturas y gastos'!$B$43/SUM($O$8:$O$657)) | Q13: =IF(OR(O13="",'Facturas y gastos'!$B$5="",P13=""),"",O13*'Facturas y gastos'!$B$5+P13) | R13: =IF(OR(Q13="",F13="",F13=0),"",Q13/F13)
A14: A26TM06007-1 | B14: 7 | C14: PG289 | D14: set de taza | E14: PCS | F14: 300 | G14: 5 | H14: 1.1 | I14: 330 | J14: =IF(OR(A14="",I14=""),"",IF(SUMIFS($I$8:$I$657,$A$8:$A$657,A14)=0,"",I14*SUMIFS('Facturas y gastos'!$D$10:$D$13,'Facturas y gastos'!$A$10:$A$13,A14)/SUMIFS($I$8:$I$657,$A$8:$A$657,A14))) -> 330 | K14: =IF(J14="","",IF(SUMIFS('Facturas y gastos'!$D$10:$D$13,'Facturas y gastos'!$A$10:$A$13,A14)=0,"",J14*SUMIFS('Facturas y gastos'!$G$10:$G$13,'Facturas y gastos'!$A$10:$A$13,A14)/SUMIFS('Facturas y gastos'!$D$10:$D$13,'Facturas y gastos'!$A$10:$A$13,A14))) -> 3.3000175 | L14: =IF(J14="","",IF(SUMIFS('Facturas y gastos'!$D$10:$D$13,'Facturas y gastos'!$A$10:$A$13,A14)=0,"",J14*SUMIFS('Facturas y gastos'!$H$10:$H$13,'Facturas y gastos'!$A$10:$A$13,A14)/SUMIFS('Facturas y gastos'!$D$10:$D$13,'Facturas y gastos'!$A$10:$A$13,A14))) -> 9.8999795 | M14: =IF(J14="","",IF(SUMIFS('Facturas y gastos'!$D$10:$D$13,'Facturas y gastos'!$A$10:$A$13,A14)=0,"",J14*SUMIFS('Facturas y gastos'!$I$10:$I$13,'Facturas y gastos'!$A$10:$A$13,A14)/SUMIFS('Facturas y gastos'!$D$10:$D$13,'Facturas y gastos'!$A$10:$A$13,A14))) -> 57.709216 | N14: =IF(J14="","",IF(SUMIFS('Facturas y gastos'!$D$10:$D$13,'Facturas y gastos'!$A$10:$A$13,A14)=0,"",J14*SUMIFS('Facturas y gastos'!$J$10:$J$13,'Facturas y gastos'!$A$10:$A$13,A14)/SUMIFS('Facturas y gastos'!$D$10:$D$13,'Facturas y gastos'!$A$10:$A$13,A14))) -> 0 | O14: =IF(J14="","",J14-K14+L14+M14+N14) -> 394.30918 | P14: =IF(OR(O14="",'Facturas y gastos'!$B$24="",'Facturas y gastos'!$B$45<>"OK",SUM($O$8:$O$657)=0),"",O14*'Facturas y gastos'!$B$43/SUM($O$8:$O$657)) | Q14: =IF(OR(O14="",'Facturas y gastos'!$B$5="",P14=""),"",O14*'Facturas y gastos'!$B$5+P14) | R14: =IF(OR(Q14="",F14="",F14=0),"",Q14/F14)
A15: A26TM06007-1 | B15: 8 | C15: PG302 | D15: set de taza | E15: PCS | F15: 180 | G15: 5 | H15: 3.37 | I15: 606.6 | J15: =IF(OR(A15="",I15=""),"",IF(SUMIFS($I$8:$I$657,$A$8:$A$657,A15)=0,"",I15*SUMIFS('Facturas y gastos'!$D$10:$D$13,'Facturas y gastos'!$A$10:$A$13,A15)/SUMIFS($I$8:$I$657,$A$8:$A$657,A15))) -> 606.6 | K15: =IF(J15="","",IF(SUMIFS('Facturas y gastos'!$D$10:$D$13,'Facturas y gastos'!$A$10:$A$13,A15)=0,"",J15*SUMIFS('Facturas y gastos'!$G$10:$G$13,'Facturas y gastos'!$A$10:$A$13,A15)/SUMIFS('Facturas y gastos'!$D$10:$D$13,'Facturas y gastos'!$A$10:$A$13,A15))) -> 6.0660322 | L15: =IF(J15="","",IF(SUMIFS('Facturas y gastos'!$D$10:$D$13,'Facturas y gastos'!$A$10:$A$13,A15)=0,"",J15*SUMIFS('Facturas y gastos'!$H$10:$H$13,'Facturas y gastos'!$A$10:$A$13,A15)/SUMIFS('Facturas y gastos'!$D$10:$D$13,'Facturas y gastos'!$A$10:$A$13,A15))) -> 18.197962 | M15: =IF(J15="","",IF(SUMIFS('Facturas y gastos'!$D$10:$D$13,'Facturas y gastos'!$A$10:$A$13,A15)=0,"",J15*SUMIFS('Facturas y gastos'!$I$10:$I$13,'Facturas y gastos'!$A$10:$A$13,A15)/SUMIFS('Facturas y gastos'!$D$10:$D$13,'Facturas y gastos'!$A$10:$A$13,A15))) -> 106.08003 | N15: =IF(J15="","",IF(SUMIFS('Facturas y gastos'!$D$10:$D$13,'Facturas y gastos'!$A$10:$A$13,A15)=0,"",J15*SUMIFS('Facturas y gastos'!$J$10:$J$13,'Facturas y gastos'!$A$10:$A$13,A15)/SUMIFS('Facturas y gastos'!$D$10:$D$13,'Facturas y gastos'!$A$10:$A$13,A15))) -> 0 | O15: =IF(J15="","",J15-K15+L15+M15+N15) -> 724.81196 | P15: =IF(OR(O15="",'Facturas y gastos'!$B$24="",'Facturas y gastos'!$B$45<>"OK",SUM($O$8:$O$657)=0),"",O15*'Facturas y gastos'!$B$43/SUM($O$8:$O$657)) | Q15: =IF(OR(O15="",'Facturas y gastos'!$B$5="",P15=""),"",O15*'Facturas y gastos'!$B$5+P15) | R15: =IF(OR(Q15="",F15="",F15=0),"",Q15/F15)
A16: A26TM06007-1 | B16: 9 | C16: PG328 | D16: Organizadores de especies | E16: PCS | F16: 40 | G16: 5 | H16: 9.28 | I16: 371.2 | J16: =IF(OR(A16="",I16=""),"",IF(SUMIFS($I$8:$I$657,$A$8:$A$657,A16)=0,"",I16*SUMIFS('Facturas y gastos'!$D$10:$D$13,'Facturas y gastos'!$A$10:$A$13,A16)/SUMIFS($I$8:$I$657,$A$8:$A$657,A16))) -> 371.2 | K16: =IF(J16="","",IF(SUMIFS('Facturas y gastos'!$D$10:$D$13,'Facturas y gastos'!$A$10:$A$13,A16)=0,"",J16*SUMIFS('Facturas y gastos'!$G$10:$G$13,'Facturas y gastos'!$A$10:$A$13,A16)/SUMIFS('Facturas y gastos'!$D$10:$D$13,'Facturas y gastos'!$A$10:$A$13,A16))) -> 3.7120197 | L16: =IF(J16="","",IF(SUMIFS('Facturas y gastos'!$D$10:$D$13,'Facturas y gastos'!$A$10:$A$13,A16)=0,"",J16*SUMIFS('Facturas y gastos'!$H$10:$H$13,'Facturas y gastos'!$A$10:$A$13,A16)/SUMIFS('Facturas y gastos'!$D$10:$D$13,'Facturas y gastos'!$A$10:$A$13,A16))) -> 11.135977 | M16: =IF(J16="","",IF(SUMIFS('Facturas y gastos'!$D$10:$D$13,'Facturas y gastos'!$A$10:$A$13,A16)=0,"",J16*SUMIFS('Facturas y gastos'!$I$10:$I$13,'Facturas y gastos'!$A$10:$A$13,A16)/SUMIFS('Facturas y gastos'!$D$10:$D$13,'Facturas y gastos'!$A$10:$A$13,A16))) -> 64.914125 | N16: =IF(J16="","",IF(SUMIFS('Facturas y gastos'!$D$10:$D$13,'Facturas y gastos'!$A$10:$A$13,A16)=0,"",J16*SUMIFS('Facturas y gastos'!$J$10:$J$13,'Facturas y gastos'!$A$10:$A$13,A16)/SUMIFS('Facturas y gastos'!$D$10:$D$13,'Facturas y gastos'!$A$10:$A$13,A16))) -> 0 | O16: =IF(J16="","",J16-K16+L16+M16+N16) -> 443.53808 | P16: =IF(OR(O16="",'Facturas y gastos'!$B$24="",'Facturas y gastos'!$B$45<>"OK",SUM($O$8:$O$657)=0),"",O16*'Facturas y gastos'!$B$43/SUM($O$8:$O$657)) | Q16: =IF(OR(O16="",'Facturas y gastos'!$B$5="",P16=""),"",O16*'Facturas y gastos'!$B$5+P16) | R16: =IF(OR(Q16="",F16="",F16=0),"",Q16/F16)
A17: A26TM06007-1 | B17: 10 | C17: PG329 | D17: Organizadores de especies | E17: PCS | F17: 60 | G17: 10 | H17: 7.67 | I17: 460.2 | J17: =IF(OR(A17="",I17=""),"",IF(SUMIFS($I$8:$I$657,$A$8:$A$657,A17)=0,"",I17*SUMIFS('Facturas y gastos'!$D$10:$D$13,'Facturas y gastos'!$A$10:$A$13,A17)/SUMIFS($I$8:$I$657,$A$8:$A$657,A17))) -> 460.2 | K17: =IF(J17="","",IF(SUMIFS('Facturas y gastos'!$D$10:$D$13,'Facturas y gastos'!$A$10:$A$13,A17)=0,"",J17*SUMIFS('Facturas y gastos'!$G$10:$G$13,'Facturas y gastos'!$A$10:$A$13,A17)/SUMIFS('Facturas y gastos'!$D$10:$D$13,'Facturas y gastos'!$A$10:$A$13,A17))) -> 4.6020244 | L17: =IF(J17="","",IF(SUMIFS('Facturas y gastos'!$D$10:$D$13,'Facturas y gastos'!$A$10:$A$13,A17)=0,"",J17*SUMIFS('Facturas y gastos'!$H$10:$H$13,'Facturas y gastos'!$A$10:$A$13,A17)/SUMIFS('Facturas y gastos'!$D$10:$D$13,'Facturas y gastos'!$A$10:$A$13,A17))) -> 13.805971 | M17: =IF(J17="","",IF(SUMIFS('Facturas y gastos'!$D$10:$D$13,'Facturas y gastos'!$A$10:$A$13,A17)=0,"",J17*SUMIFS('Facturas y gastos'!$I$10:$I$13,'Facturas y gastos'!$A$10:$A$13,A17)/SUMIFS('Facturas y gastos'!$D$10:$D$13,'Facturas y gastos'!$A$10:$A$13,A17))) -> 80.478125 | N17: =IF(J17="","",IF(SUMIFS('Facturas y gastos'!$D$10:$D$13,'Facturas y gastos'!$A$10:$A$13,A17)=0,"",J17*SUMIFS('Facturas y gastos'!$J$10:$J$13,'Facturas y gastos'!$A$10:$A$13,A17)/SUMIFS('Facturas y gastos'!$D$10:$D$13,'Facturas y gastos'!$A$10:$A$13,A17))) -> 0 | O17: =IF(J17="","",J17-K17+L17+M17+N17) -> 549.88207 | P17: =IF(OR(O17="",'Facturas y gastos'!$B$24="",'Facturas y gastos'!$B$45<>"OK",SUM($O$8:$O$657)=0),"",O17*'Facturas y gastos'!$B$43/SUM($O$8:$O$657)) | Q17: =IF(OR(O17="",'Facturas y gastos'!$B$5="",P17=""),"",O17*'Facturas y gastos'!$B$5+P17) | R17: =IF(OR(Q17="",F17="",F17=0),"",Q17/F17)
A18: A26TM06007-1 | B18: 11 | C18: PG330 | D18: Jarra con grifo | E18: PCS | F18: 30 | G18: 5 | H18: 10.46 | I18: 313.8 | J18: =IF(OR(A18="",I18=""),"",IF(SUMIFS($I$8:$I$657,$A$8:$A$657,A18)=0,"",I18*SUMIFS('Facturas y gastos'!$D$10:$D$13,'Facturas y gastos'!$A$10:$A$13,A18)/SUMIFS($I$8:$I$657,$A$8:$A$657,A18))) -> 313.8 | K18: =IF(J18="","",IF(SUMIFS('Facturas y gastos'!$D$10:$D$13,'Facturas y gastos'!$A$10:$A$13,A18)=0,"",J18*SUMIFS('Facturas y gastos'!$G$10:$G$13,'Facturas y gastos'!$A$10:$A$13,A18)/SUMIFS('Facturas y gastos'!$D$10:$D$13,'Facturas y gastos'!$A$10:$A$13,A18))) -> 3.1380167 | L18: =IF(J18="","",IF(SUMIFS('Facturas y gastos'!$D$10:$D$13,'Facturas y gastos'!$A$10:$A$13,A18)=0,"",J18*SUMIFS('Facturas y gastos'!$H$10:$H$13,'Facturas y gastos'!$A$10:$A$13,A18)/SUMIFS('Facturas y gastos'!$D$10:$D$13,'Facturas y gastos'!$A$10:$A$13,A18))) -> 9.4139806 | M18: =IF(J18="","",IF(SUMIFS('Facturas y gastos'!$D$10:$D$13,'Facturas y gastos'!$A$10:$A$13,A18)=0,"",J18*SUMIFS('Facturas y gastos'!$I$10:$I$13,'Facturas y gastos'!$A$10:$A$13,A18)/SUMIFS('Facturas y gastos'!$D$10:$D$13,'Facturas y gastos'!$A$10:$A$13,A18))) -> 54.876218 | N18: =IF(J18="","",IF(SUMIFS('Facturas y gastos'!$D$10:$D$13,'Facturas y gastos'!$A$10:$A$13,A18)=0,"",J18*SUMIFS('Facturas y gastos'!$J$10:$J$13,'Facturas y gastos'!$A$10:$A$13,A18)/SUMIFS('Facturas y gastos'!$D$10:$D$13,'Facturas y gastos'!$A$10:$A$13,A18))) -> 0 | O18: =IF(J18="","",J18-K18+L18+M18+N18) -> 374.95218 | P18: =IF(OR(O18="",'Facturas y gastos'!$B$24="",'Facturas y gastos'!$B$45<>"OK",SUM($O$8:$O$657)=0),"",O18*'Facturas y gastos'!$B$43/SUM($O$8:$O$657)) | Q18: =IF(OR(O18="",'Facturas y gastos'!$B$5="",P18=""),"",O18*'Facturas y gastos'!$B$5+P18) | R18: =IF(OR(Q18="",F18="",F18=0),"",Q18/F18)
A19: A26TM06007-1 | B19: 12 | C19: PG332 | D19: Organizadores de especies | E19: PCS | F19: 30 | G19: 5 | H19: 9.28 | I19: 278.4 | J19: =IF(OR(A19="",I19=""),"",IF(SUMIFS($I$8:$I$657,$A$8:$A$657,A19)=0,"",I19*SUMIFS('Facturas y gastos'!$D$10:$D$13,'Facturas y gastos'!$A$10:$A$13,A19)/SUMIFS($I$8:$I$657,$A$8:$A$657,A19))) -> 278.4 | K19: =IF(J19="","",IF(SUMIFS('Facturas y gastos'!$D$10:$D$13,'Facturas y gastos'!$A$10:$A$13,A19)=0,"",J19*SUMIFS('Facturas y gastos'!$G$10:$G$13,'Facturas y gastos'!$A$10:$A$13,A19)/SUMIFS('Facturas y gastos'!$D$10:$D$13,'Facturas y gastos'!$A$10:$A$13,A19))) -> 2.7840148 | L19: =IF(J19="","",IF(SUMIFS('Facturas y gastos'!$D$10:$D$13,'Facturas y gastos'!$A$10:$A$13,A19)=0,"",J19*SUMIFS('Facturas y gastos'!$H$10:$H$13,'Facturas y gastos'!$A$10:$A$13,A19)/SUMIFS('Facturas y gastos'!$D$10:$D$13,'Facturas y gastos'!$A$10:$A$13,A19))) -> 8.3519827 | M19: =IF(J19="","",IF(SUMIFS('Facturas y gastos'!$D$10:$D$13,'Facturas y gastos'!$A$10:$A$13,A19)=0,"",J19*SUMIFS('Facturas y gastos'!$I$10:$I$13,'Facturas y gastos'!$A$10:$A$13,A19)/SUMIFS('Facturas y gastos'!$D$10:$D$13,'Facturas y gastos'!$A$10:$A$13,A19))) -> 48.685593 | N19: =IF(J19="","",IF(SUMIFS('Facturas y gastos'!$D$10:$D$13,'Facturas y gastos'!$A$10:$A$13,A19)=0,"",J19*SUMIFS('Facturas y gastos'!$J$10:$J$13,'Facturas y gastos'!$A$10:$A$13,A19)/SUMIFS('Facturas y gastos'!$D$10:$D$13,'Facturas y gastos'!$A$10:$A$13,A19))) -> 0 | O19: =IF(J19="","",J19-K19+L19+M19+N19) -> 332.65356 | P19: =IF(OR(O19="",'Facturas y gastos'!$B$24="",'Facturas y gastos'!$B$45<>"OK",SUM($O$8:$O$657)=0),"",O19*'Facturas y gastos'!$B$43/SUM($O$8:$O$657)) | Q19: =IF(OR(O19="",'Facturas y gastos'!$B$5="",P19=""),"",O19*'Facturas y gastos'!$B$5+P19) | R19: =IF(OR(Q19="",F19="",F19=0),"",Q19/F19)
... A81: A26TM06007-1 | B81: 74 | C81: PG198 | D81: Piedra aromática3 aromas | E81: PCS | F81: 60 | G81: 5 | H81: 5.97 | I81: 358.21 | J81: =IF(OR(A81="",I81=""),"",IF(SUMIFS($I$8:$I$657,$A$8:$A$657,A81)=0,"",I81*SUMIFS('Facturas y gastos'!$D$10:$D$13,'Facturas y gastos'!$A$10:$A$13,A81)/SUMIFS($I$8:$I$657,$A$8:$A$657,A81))) -> 358.21 | K81: =IF(J81="","",IF(SUMIFS('Facturas y gastos'!$D$10:$D$13,'Facturas y gastos'!$A$10:$A$13,A81)=0,"",J81*SUMIFS('Facturas y gastos'!$G$10:$G$13,'Facturas y gastos'!$A$10:$A$13,A81)/SUMIFS('Facturas y gastos'!$D$10:$D$13,'Facturas y gastos'!$A$10:$A$13,A81))) -> 3.582119 | L81: =IF(J81="","",IF(SUMIFS('Facturas y gastos'!$D$10:$D$13,'Facturas y gastos'!$A$10:$A$13,A81)=0,"",J81*SUMIFS('Facturas y gastos'!$H$10:$H$13,'Facturas y gastos'!$A$10:$A$13,A81)/SUMIFS('Facturas y gastos'!$D$10:$D$13,'Facturas y gastos'!$A$10:$A$13,A81))) -> 10.746278 | M81: =IF(J81="","",IF(SUMIFS('Facturas y gastos'!$D$10:$D$13,'Facturas y gastos'!$A$10:$A$13,A81)=0,"",J81*SUMIFS('Facturas y gastos'!$I$10:$I$13,'Facturas y gastos'!$A$10:$A$13,A81)/SUMIFS('Facturas y gastos'!$D$10:$D$13,'Facturas y gastos'!$A$10:$A$13,A81))) -> 62.64248 | N81: =IF(J81="","",IF(SUMIFS('Facturas y gastos'!$D$10:$D$13,'Facturas y gastos'!$A$10:$A$13,A81)=0,"",J81*SUMIFS('Facturas y gastos'!$J$10:$J$13,'Facturas y gastos'!$A$10:$A$13,A81)/SUMIFS('Facturas y gastos'!$D$10:$D$13,'Facturas y gastos'!$A$10:$A$13,A81))) -> 0 | O81: =IF(J81="","",J81-K81+L81+M81+N81) -> 428.01664 | P81: =IF(OR(O81="",'Facturas y gastos'!$B$24="",'Facturas y gastos'!$B$45<>"OK",SUM($O$8:$O$657)=0),"",O81*'Facturas y gastos'!$B$43/SUM($O$8:$O$657)) | Q81: =IF(OR(O81="",'Facturas y gastos'!$B$5="",P81=""),"",O81*'Facturas y gastos'!$B$5+P81) | R81: =IF(OR(Q81="",F81="",F81=0),"",Q81/F81)
A82: A26TM06007-1 | B82: 75 | C82: PG204 | E82: PCS | F82: 240 | G82: 4 | H82: 2.51 | I82: 601.79 | J82: =IF(OR(A82="",I82=""),"",IF(SUMIFS($I$8:$I$657,$A$8:$A$657,A82)=0,"",I82*SUMIFS('Facturas y gastos'!$D$10:$D$13,'Facturas y gastos'!$A$10:$A$13,A82)/SUMIFS($I$8:$I$657,$A$8:$A$657,A82))) -> 601.79 | K82: =IF(J82="","",IF(SUMIFS('Facturas y gastos'!$D$10:$D$13,'Facturas y gastos'!$A$10:$A$13,A82)=0,"",J82*SUMIFS('Facturas y gastos'!$G$10:$G$13,'Facturas y gastos'!$A$10:$A$13,A82)/SUMIFS('Facturas y gastos'!$D$10:$D$13,'Facturas y gastos'!$A$10:$A$13,A82))) -> 6.017932 | L82: =IF(J82="","",IF(SUMIFS('Facturas y gastos'!$D$10:$D$13,'Facturas y gastos'!$A$10:$A$13,A82)=0,"",J82*SUMIFS('Facturas y gastos'!$H$10:$H$13,'Facturas y gastos'!$A$10:$A$13,A82)/SUMIFS('Facturas y gastos'!$D$10:$D$13,'Facturas y gastos'!$A$10:$A$13,A82))) -> 18.053663 | M82: =IF(J82="","",IF(SUMIFS('Facturas y gastos'!$D$10:$D$13,'Facturas y gastos'!$A$10:$A$13,A82)=0,"",J82*SUMIFS('Facturas y gastos'!$I$10:$I$13,'Facturas y gastos'!$A$10:$A$13,A82)/SUMIFS('Facturas y gastos'!$D$10:$D$13,'Facturas y gastos'!$A$10:$A$13,A82))) -> 105.23888 | N82: =IF(J82="","",IF(SUMIFS('Facturas y gastos'!$D$10:$D$13,'Facturas y gastos'!$A$10:$A$13,A82)=0,"",J82*SUMIFS('Facturas y gastos'!$J$10:$J$13,'Facturas y gastos'!$A$10:$A$13,A82)/SUMIFS('Facturas y gastos'!$D$10:$D$13,'Facturas y gastos'!$A$10:$A$13,A82))) -> 0 | O82: =IF(J82="","",J82-K82+L82+M82+N82) -> 719.06461 | P82: =IF(OR(O82="",'Facturas y gastos'!$B$24="",'Facturas y gastos'!$B$45<>"OK",SUM($O$8:$O$657)=0),"",O82*'Facturas y gastos'!$B$43/SUM($O$8:$O$657)) | Q82: =IF(OR(O82="",'Facturas y gastos'!$B$5="",P82=""),"",O82*'Facturas y gastos'!$B$5+P82) | R82: =IF(OR(Q82="",F82="",F82=0),"",Q82/F82)
A83: A26TM06007-1 | B83: 76 | C83: PG205 | D83: DecoraciónMadera de pino | E83: PCS | F83: 300 | G83: 4 | H83: 2.36 | I83: 707.46 | J83: =IF(OR(A83="",I83=""),"",IF(SUMIFS($I$8:$I$657,$A$8:$A$657,A83)=0,"",I83*SUMIFS('Facturas y gastos'!$D$10:$D$13,'Facturas y gastos'!$A$10:$A$13,A83)/SUMIFS($I$8:$I$657,$A$8:$A$657,A83))) -> 707.46 | K83: =IF(J83="","",IF(SUMIFS('Facturas y gastos'!$D$10:$D$13,'Facturas y gastos'!$A$10:$A$13,A83)=0,"",J83*SUMIFS('Facturas y gastos'!$G$10:$G$13,'Facturas y gastos'!$A$10:$A$13,A83)/SUMIFS('Facturas y gastos'!$D$10:$D$13,'Facturas y gastos'!$A$10:$A$13,A83))) -> 7.0746376 | L83: =IF(J83="","",IF(SUMIFS('Facturas y gastos'!$D$10:$D$13,'Facturas y gastos'!$A$10:$A$13,A83)=0,"",J83*SUMIFS('Facturas y gastos'!$H$10:$H$13,'Facturas y gastos'!$A$10:$A$13,A83)/SUMIFS('Facturas y gastos'!$D$10:$D$13,'Facturas y gastos'!$A$10:$A$13,A83))) -> 21.223756 | M83: =IF(J83="","",IF(SUMIFS('Facturas y gastos'!$D$10:$D$13,'Facturas y gastos'!$A$10:$A$13,A83)=0,"",J83*SUMIFS('Facturas y gastos'!$I$10:$I$13,'Facturas y gastos'!$A$10:$A$13,A83)/SUMIFS('Facturas y gastos'!$D$10:$D$13,'Facturas y gastos'!$A$10:$A$13,A83))) -> 123.71807 | N83: =IF(J83="","",IF(SUMIFS('Facturas y gastos'!$D$10:$D$13,'Facturas y gastos'!$A$10:$A$13,A83)=0,"",J83*SUMIFS('Facturas y gastos'!$J$10:$J$13,'Facturas y gastos'!$A$10:$A$13,A83)/SUMIFS('Facturas y gastos'!$D$10:$D$13,'Facturas y gastos'!$A$10:$A$13,A83))) -> 0 | O83: =IF(J83="","",J83-K83+L83+M83+N83) -> 845.32719 | P83: =IF(OR(O83="",'Facturas y gastos'!$B$24="",'Facturas y gastos'!$B$45<>"OK",SUM($O$8:$O$657)=0),"",O83*'Facturas y gastos'!$B$43/SUM($O$8:$O$657)) | Q83: =IF(OR(O83="",'Facturas y gastos'!$B$5="",P83=""),"",O83*'Facturas y gastos'!$B$5+P83) | R83: =IF(OR(Q83="",F83="",F83=0),"",Q83/F83)
A84: A26TM06007-1 | B84: 77 | C84: PG205-1 | D84: DecoraciónMadera de pino | E84: PCS | F84: 300 | G84: 4 | H84: 2.04 | I84: 613.43 | J84: =IF(OR(A84="",I84=""),"",IF(SUMIFS($I$8:$I$657,$A$8:$A$657,A84)=0,"",I84*SUMIFS('Facturas y gastos'!$D$10:$D$13,'Facturas y gastos'!$A$10:$A$13,A84)/SUMIFS($I$8:$I$657,$A$8:$A$657,A84))) -> 613.43 | K84: =IF(J84="","",IF(SUMIFS('Facturas y gastos'!$D$10:$D$13,'Facturas y gastos'!$A$10:$A$13,A84)=0,"",J84*SUMIFS('Facturas y gastos'!$G$10:$G$13,'Facturas y gastos'!$A$10:$A$13,A84)/SUMIFS('Facturas y gastos'!$D$10:$D$13,'Facturas y gastos'!$A$10:$A$13,A84))) -> 6.1343326 | L84: =IF(J84="","",IF(SUMIFS('Facturas y gastos'!$D$10:$D$13,'Facturas y gastos'!$A$10:$A$13,A84)=0,"",J84*SUMIFS('Facturas y gastos'!$H$10:$H$13,'Facturas y gastos'!$A$10:$A$13,A84)/SUMIFS('Facturas y gastos'!$D$10:$D$13,'Facturas y gastos'!$A$10:$A$13,A84))) -> 18.402862 | M84: =IF(J84="","",IF(SUMIFS('Facturas y gastos'!$D$10:$D$13,'Facturas y gastos'!$A$10:$A$13,A84)=0,"",J84*SUMIFS('Facturas y gastos'!$I$10:$I$13,'Facturas y gastos'!$A$10:$A$13,A84)/SUMIFS('Facturas y gastos'!$D$10:$D$13,'Facturas y gastos'!$A$10:$A$13,A84))) -> 107.27444 | N84: =IF(J84="","",IF(SUMIFS('Facturas y gastos'!$D$10:$D$13,'Facturas y gastos'!$A$10:$A$13,A84)=0,"",J84*SUMIFS('Facturas y gastos'!$J$10:$J$13,'Facturas y gastos'!$A$10:$A$13,A84)/SUMIFS('Facturas y gastos'!$D$10:$D$13,'Facturas y gastos'!$A$10:$A$13,A84))) -> 0 | O84: =IF(J84="","",J84-K84+L84+M84+N84) -> 732.97297 | P84: =IF(OR(O84="",'Facturas y gastos'!$B$24="",'Facturas y gastos'!$B$45<>"OK",SUM($O$8:$O$657)=0),"",O84*'Facturas y gastos'!$B$43/SUM($O$8:$O$657)) | Q84: =IF(OR(O84="",'Facturas y gastos'!$B$5="",P84=""),"",O84*'Facturas y gastos'!$B$5+P84) | R84: =IF(OR(Q84="",F84="",F84=0),"",Q84/F84)
A85: A26TM06007-1 | B85: 78 | C85: PG206 | D85: DecoraciónMadera de pino | E85: PCS | F85: 400 | G85: 4 | H85: 2.36 | I85: 943.28 | J85: =IF(OR(A85="",I85=""),"",IF(SUMIFS($I$8:$I$657,$A$8:$A$657,A85)=0,"",I85*SUMIFS('Facturas y gastos'!$D$10:$D$13,'Facturas y gastos'!$A$10:$A$13,A85)/SUMIFS($I$8:$I$657,$A$8:$A$657,A85))) -> 943.28 | K85: =IF(J85="","",IF(SUMIFS('Facturas y gastos'!$D$10:$D$13,'Facturas y gastos'!$A$10:$A$13,A85)=0,"",J85*SUMIFS('Facturas y gastos'!$G$10:$G$13,'Facturas y gastos'!$A$10:$A$13,A85)/SUMIFS('Facturas y gastos'!$D$10:$D$13,'Facturas y gastos'!$A$10:$A$13,A85))) -> 9.4328501 | L85: =IF(J85="","",IF(SUMIFS('Facturas y gastos'!$D$10:$D$13,'Facturas y gastos'!$A$10:$A$13,A85)=0,"",J85*SUMIFS('Facturas y gastos'!$H$10:$H$13,'Facturas y gastos'!$A$10:$A$13,A85)/SUMIFS('Facturas y gastos'!$D$10:$D$13,'Facturas y gastos'!$A$10:$A$13,A85))) -> 28.298342 | M85: =IF(J85="","",IF(SUMIFS('Facturas y gastos'!$D$10:$D$13,'Facturas y gastos'!$A$10:$A$13,A85)=0,"",J85*SUMIFS('Facturas y gastos'!$I$10:$I$13,'Facturas y gastos'!$A$10:$A$13,A85)/SUMIFS('Facturas y gastos'!$D$10:$D$13,'Facturas y gastos'!$A$10:$A$13,A85))) -> 164.95742 | N85: =IF(J85="","",IF(SUMIFS('Facturas y gastos'!$D$10:$D$13,'Facturas y gastos'!$A$10:$A$13,A85)=0,"",J85*SUMIFS('Facturas y gastos'!$J$10:$J$13,'Facturas y gastos'!$A$10:$A$13,A85)/SUMIFS('Facturas y gastos'!$D$10:$D$13,'Facturas y gastos'!$A$10:$A$13,A85))) -> 0 | O85: =IF(J85="","",J85-K85+L85+M85+N85) -> 1127.1029 | P85: =IF(OR(O85="",'Facturas y gastos'!$B$24="",'Facturas y gastos'!$B$45<>"OK",SUM($O$8:$O$657)=0),"",O85*'Facturas y gastos'!$B$43/SUM($O$8:$O$657)) | Q85: =IF(OR(O85="",'Facturas y gastos'!$B$5="",P85=""),"",O85*'Facturas y gastos'!$B$5+P85) | R85: =IF(OR(Q85="",F85="",F85=0),"",Q85/F85)
A86: A26TM06007-1 | B86: 79 | C86: PG208 | D86: DecoraciónMadera de pino | E86: PCS | F86: 240 | G86: 4 | H86: 2.67 | I86: 641.19 | J86: =IF(OR(A86="",I86=""),"",IF(SUMIFS($I$8:$I$657,$A$8:$A$657,A86)=0,"",I86*SUMIFS('Facturas y gastos'!$D$10:$D$13,'Facturas y gastos'!$A$10:$A$13,A86)/SUMIFS($I$8:$I$657,$A$8:$A$657,A86))) -> 641.19 | K86: =IF(J86="","",IF(SUMIFS('Facturas y gastos'!$D$10:$D$13,'Facturas y gastos'!$A$10:$A$13,A86)=0,"",J86*SUMIFS('Facturas y gastos'!$G$10:$G$13,'Facturas y gastos'!$A$10:$A$13,A86)/SUMIFS('Facturas y gastos'!$D$10:$D$13,'Facturas y gastos'!$A$10:$A$13,A86))) -> 6.4119341 | L86: =IF(J86="","",IF(SUMIFS('Facturas y gastos'!$D$10:$D$13,'Facturas y gastos'!$A$10:$A$13,A86)=0,"",J86*SUMIFS('Facturas y gastos'!$H$10:$H$13,'Facturas y gastos'!$A$10:$A$13,A86)/SUMIFS('Facturas y gastos'!$D$10:$D$13,'Facturas y gastos'!$A$10:$A$13,A86))) -> 19.23566 | M86: =IF(J86="","",IF(SUMIFS('Facturas y gastos'!$D$10:$D$13,'Facturas y gastos'!$A$10:$A$13,A86)=0,"",J86*SUMIFS('Facturas y gastos'!$I$10:$I$13,'Facturas y gastos'!$A$10:$A$13,A86)/SUMIFS('Facturas y gastos'!$D$10:$D$13,'Facturas y gastos'!$A$10:$A$13,A86))) -> 112.12901 | N86: =IF(J86="","",IF(SUMIFS('Facturas y gastos'!$D$10:$D$13,'Facturas y gastos'!$A$10:$A$13,A86)=0,"",J86*SUMIFS('Facturas y gastos'!$J$10:$J$13,'Facturas y gastos'!$A$10:$A$13,A86)/SUMIFS('Facturas y gastos'!$D$10:$D$13,'Facturas y gastos'!$A$10:$A$13,A86))) -> 0 | O86: =IF(J86="","",J86-K86+L86+M86+N86) -> 766.14273 | P86: =IF(OR(O86="",'Facturas y gastos'!$B$24="",'Facturas y gastos'!$B$45<>"OK",SUM($O$8:$O$657)=0),"",O86*'Facturas y gastos'!$B$43/SUM($O$8:$O$657)) | Q86: =IF(OR(O86="",'Facturas y gastos'!$B$5="",P86=""),"",O86*'Facturas y gastos'!$B$5+P86) | R86: =IF(OR(Q86="",F86="",F86=0),"",Q86/F86)
A87: A26TM06007-1 | B87: 80 | C87: PG212 | E87: PCS | F87: 240 | G87: 2 | H87: 2.36 | I87: 565.97 | J87: =IF(OR(A87="",I87=""),"",IF(SUMIFS($I$8:$I$657,$A$8:$A$657,A87)=0,"",I87*SUMIFS('Facturas y gastos'!$D$10:$D$13,'Facturas y gastos'!$A$10:$A$13,A87)/SUMIFS($I$8:$I$657,$A$8:$A$657,A87))) -> 565.97 | K87: =IF(J87="","",IF(SUMIFS('Facturas y gastos'!$D$10:$D$13,'Facturas y gastos'!$A$10:$A$13,A87)=0,"",J87*SUMIFS('Facturas y gastos'!$G$10:$G$13,'Facturas y gastos'!$A$10:$A$13,A87)/SUMIFS('Facturas y gastos'!$D$10:$D$13,'Facturas y gastos'!$A$10:$A$13,A87))) -> 5.6597301 | L87: =IF(J87="","",IF(SUMIFS('Facturas y gastos'!$D$10:$D$13,'Facturas y gastos'!$A$10:$A$13,A87)=0,"",J87*SUMIFS('Facturas y gastos'!$H$10:$H$13,'Facturas y gastos'!$A$10:$A$13,A87)/SUMIFS('Facturas y gastos'!$D$10:$D$13,'Facturas y gastos'!$A$10:$A$13,A87))) -> 16.979065 | M87: =IF(J87="","",IF(SUMIFS('Facturas y gastos'!$D$10:$D$13,'Facturas y gastos'!$A$10:$A$13,A87)=0,"",J87*SUMIFS('Facturas y gastos'!$I$10:$I$13,'Facturas y gastos'!$A$10:$A$13,A87)/SUMIFS('Facturas y gastos'!$D$10:$D$13,'Facturas y gastos'!$A$10:$A$13,A87))) -> 98.974804 | N87: =IF(J87="","",IF(SUMIFS('Facturas y gastos'!$D$10:$D$13,'Facturas y gastos'!$A$10:$A$13,A87)=0,"",J87*SUMIFS('Facturas y gastos'!$J$10:$J$13,'Facturas y gastos'!$A$10:$A$13,A87)/SUMIFS('Facturas y gastos'!$D$10:$D$13,'Facturas y gastos'!$A$10:$A$13,A87))) -> 0 | O87: =IF(J87="","",J87-K87+L87+M87+N87) -> 676.26414 | P87: =IF(OR(O87="",'Facturas y gastos'!$B$24="",'Facturas y gastos'!$B$45<>"OK",SUM($O$8:$O$657)=0),"",O87*'Facturas y gastos'!$B$43/SUM($O$8:$O$657)) | Q87: =IF(OR(O87="",'Facturas y gastos'!$B$5="",P87=""),"",O87*'Facturas y gastos'!$B$5+P87) | R87: =IF(OR(Q87="",F87="",F87=0),"",Q87/F87)
A88: A26TM06007-1 | B88: 81 | C88: PG214-1 | D88: Soporte para platos negro | E88: PCS | F88: 180 | G88: 3 | H88: 2.54 | I88: 456.72 | J88: =IF(OR(A88="",I88=""),"",IF(SUMIFS($I$8:$I$657,$A$8:$A$657,A88)=0,"",I88*SUMIFS('Facturas y gastos'!$D$10:$D$13,'Facturas y gastos'!$A$10:$A$13,A88)/SUMIFS($I$8:$I$657,$A$8:$A$657,A88))) -> 456.72 | K88: =IF(J88="","",IF(SUMIFS('Facturas y gastos'!$D$10:$D$13,'Facturas y gastos'!$A$10:$A$13,A88)=0,"",J88*SUMIFS('Facturas y gastos'!$G$10:$G$13,'Facturas y gastos'!$A$10:$A$13,A88)/SUMIFS('Facturas y gastos'!$D$10:$D$13,'Facturas y gastos'!$A$10:$A$13,A88))) -> 4.5672243 | L88: =IF(J88="","",IF(SUMIFS('Facturas y gastos'!$D$10:$D$13,'Facturas y gastos'!$A$10:$A$13,A88)=0,"",J88*SUMIFS('Facturas y gastos'!$H$10:$H$13,'Facturas y gastos'!$A$10:$A$13,A88)/SUMIFS('Facturas y gastos'!$D$10:$D$13,'Facturas y gastos'!$A$10:$A$13,A88))) -> 13.701572 | M88: =IF(J88="","",IF(SUMIFS('Facturas y gastos'!$D$10:$D$13,'Facturas y gastos'!$A$10:$A$13,A88)=0,"",J88*SUMIFS('Facturas y gastos'!$I$10:$I$13,'Facturas y gastos'!$A$10:$A$13,A88)/SUMIFS('Facturas y gastos'!$D$10:$D$13,'Facturas y gastos'!$A$10:$A$13,A88))) -> 79.869555 | N88: =IF(J88="","",IF(SUMIFS('Facturas y gastos'!$D$10:$D$13,'Facturas y gastos'!$A$10:$A$13,A88)=0,"",J88*SUMIFS('Facturas y gastos'!$J$10:$J$13,'Facturas y gastos'!$A$10:$A$13,A88)/SUMIFS('Facturas y gastos'!$D$10:$D$13,'Facturas y gastos'!$A$10:$A$13,A88))) -> 0 | O88: =IF(J88="","",J88-K88+L88+M88+N88) -> 545.7239 | P88: =IF(OR(O88="",'Facturas y gastos'!$B$24="",'Facturas y gastos'!$B$45<>"OK",SUM($O$8:$O$657)=0),"",O88*'Facturas y gastos'!$B$43/SUM($O$8:$O$657)) | Q88: =IF(OR(O88="",'Facturas y gastos'!$B$5="",P88=""),"",O88*'Facturas y gastos'!$B$5+P88) | R88: =IF(OR(Q88="",F88="",F88=0),"",Q88/F88)
A89: A26TM06007-1 | B89: 82 | C89: PG214-2 | D89: Soporte para platos blanco | E89: PCS | F89: 180 | G89: 3 | H89: 2.54 | I89: 456.72 | J89: =IF(OR(A89="",I89=""),"",IF(SUMIFS($I$8:$I$657,$A$8:$A$657,A89)=0,"",I89*SUMIFS('Facturas y gastos'!$D$10:$D$13,'Facturas y gastos'!$A$10:$A$13,A89)/SUMIFS($I$8:$I$657,$A$8:$A$657,A89))) -> 456.72 | K89: =IF(J89="","",IF(SUMIFS('Facturas y gastos'!$D$10:$D$13,'Facturas y gastos'!$A$10:$A$13,A89)=0,"",J89*SUMIFS('Facturas y gastos'!$G$10:$G$13,'Facturas y gastos'!$A$10:$A$13,A89)/SUMIFS('Facturas y gastos'!$D$10:$D$13,'Facturas y gastos'!$A$10:$A$13,A89))) -> 4.5672243 | L89: =IF(J89="","",IF(SUMIFS('Facturas y gastos'!$D$10:$D$13,'Facturas y gastos'!$A$10:$A$13,A89)=0,"",J89*SUMIFS('Facturas y gastos'!$H$10:$H$13,'Facturas y gastos'!$A$10:$A$13,A89)/SUMIFS('Facturas y gastos'!$D$10:$D$13,'Facturas y gastos'!$A$10:$A$13,A89))) -> 13.701572 | M89: =IF(J89="","",IF(SUMIFS('Facturas y gastos'!$D$10:$D$13,'Facturas y gastos'!$A$10:$A$13,A89)=0,"",J89*SUMIFS('Facturas y gastos'!$I$10:$I$13,'Facturas y gastos'!$A$10:$A$13,A89)/SUMIFS('Facturas y gastos'!$D$10:$D$13,'Facturas y gastos'!$A$10:$A$13,A89))) -> 79.869555 | N89: =IF(J89="","",IF(SUMIFS('Facturas y gastos'!$D$10:$D$13,'Facturas y gastos'!$A$10:$A$13,A89)=0,"",J89*SUMIFS('Facturas y gastos'!$J$10:$J$13,'Facturas y gastos'!$A$10:$A$13,A89)/SUMIFS('Facturas y gastos'!$D$10:$D$13,'Facturas y gastos'!$A$10:$A$13,A89))) -> 0 | O89: =IF(J89="","",J89-K89+L89+M89+N89) -> 545.7239 | P89: =IF(OR(O89="",'Facturas y gastos'!$B$24="",'Facturas y gastos'!$B$45<>"OK",SUM($O$8:$O$657)=0),"",O89*'Facturas y gastos'!$B$43/SUM($O$8:$O$657)) | Q89: =IF(OR(O89="",'Facturas y gastos'!$B$5="",P89=""),"",O89*'Facturas y gastos'!$B$5+P89) | R89: =IF(OR(Q89="",F89="",F89=0),"",Q89/F89)
A90: A26TM06007-1 | B90: 83 | C90: PG215-1 | D90: Bandeja | E90: PCS | F90: 90 | G90: 5 | H90: 3.1 | I90: 279.4 | J90: =IF(OR(A90="",I90=""),"",IF(SUMIFS($I$8:$I$657,$A$8:$A$657,A90)=0,"",I90*SUMIFS('Facturas y gastos'!$D$10:$D$13,'Facturas y gastos'!$A$10:$A$13,A90)/SUMIFS($I$8:$I$657,$A$8:$A$657,A90))) -> 279.4 | K90: =IF(J90="","",IF(SUMIFS('Facturas y gastos'!$D$10:$D$13,'Facturas y gastos'!$A$10:$A$13,A90)=0,"",J90*SUMIFS('Facturas y gastos'!$G$10:$G$13,'Facturas y gastos'!$A$10:$A$13,A90)/SUMIFS('Facturas y gastos'!$D$10:$D$13,'Facturas y gastos'!$A$10:$A$13,A90))) -> 2.7940148 | L90: =IF(J90="","",IF(SUMIFS('Facturas y gastos'!$D$10:$D$13,'Facturas y gastos'!$A$10:$A$13,A90)=0,"",J90*SUMIFS('Facturas y gastos'!$H$10:$H$13,'Facturas y gastos'!$A$10:$A$13,A90)/SUMIFS('Facturas y gastos'!$D$10:$D$13,'Facturas y gastos'!$A$10:$A$13,A90))) -> 8.3819827 | M90: =IF(J90="","",IF(SUMIFS('Facturas y gastos'!$D$10:$D$13,'Facturas y gastos'!$A$10:$A$13,A90)=0,"",J90*SUMIFS('Facturas y gastos'!$I$10:$I$13,'Facturas y gastos'!$A$10:$A$13,A90)/SUMIFS('Facturas y gastos'!$D$10:$D$13,'Facturas y gastos'!$A$10:$A$13,A90))) -> 48.86047 | N90: =IF(J90="","",IF(SUMIFS('Facturas y gastos'!$D$10:$D$13,'Facturas y gastos'!$A$10:$A$13,A90)=0,"",J90*SUMIFS('Facturas y gastos'!$J$10:$J$13,'Facturas y gastos'!$A$10:$A$13,A90)/SUMIFS('Facturas y gastos'!$D$10:$D$13,'Facturas y gastos'!$A$10:$A$13,A90))) -> 0 | O90: =IF(J90="","",J90-K90+L90+M90+N90) -> 333.84844 | P90: =IF(OR(O90="",'Facturas y gastos'!$B$24="",'Facturas y gastos'!$B$45<>"OK",SUM($O$8:$O$657)=0),"",O90*'Facturas y gastos'!$B$43/SUM($O$8:$O$657)) | Q90: =IF(OR(O90="",'Facturas y gastos'!$B$5="",P90=""),"",O90*'Facturas y gastos'!$B$5+P90) | R90: =IF(OR(Q90="",F90="",F90=0),"",Q90/F90)
A91: A26TM06007-1 | B91: 84 | C91: PG215-2 | D91: Bandeja | E91: PCS | F91: 90 | G91: 5 | H91: 3.85 | I91: 346.57 | J91: =IF(OR(A91="",I91=""),"",IF(SUMIFS($I$8:$I$657,$A$8:$A$657,A91)=0,"",I91*SUMIFS('Facturas y gastos'!$D$10:$D$13,'Facturas y gastos'!$A$10:$A$13,A91)/SUMIFS($I$8:$I$657,$A$8:$A$657,A91))) -> 346.57 | K91: =IF(J91="","",IF(SUMIFS('Facturas y gastos'!$D$10:$D$13,'Facturas y gastos'!$A$10:$A$13,A91)=0,"",J91*SUMIFS('Facturas y gastos'!$G$10:$G$13,'Facturas y gastos'!$A$10:$A$13,A91)/SUMIFS('Facturas y gastos'!$D$10:$D$13,'Facturas y gastos'!$A$10:$A$13,A91))) -> 3.4657184 | L91: =IF(J91="","",IF(SUMIFS('Facturas y gastos'!$D$10:$D$13,'Facturas y gastos'!$A$10:$A$13,A91)=0,"",J91*SUMIFS('Facturas y gastos'!$H$10:$H$13,'Facturas y gastos'!$A$10:$A$13,A91)/SUMIFS('Facturas y gastos'!$D$10:$D$13,'Facturas y gastos'!$A$10:$A$13,A91))) -> 10.397079 | M91: =IF(J91="","",IF(SUMIFS('Facturas y gastos'!$D$10:$D$13,'Facturas y gastos'!$A$10:$A$13,A91)=0,"",J91*SUMIFS('Facturas y gastos'!$I$10:$I$13,'Facturas y gastos'!$A$10:$A$13,A91)/SUMIFS('Facturas y gastos'!$D$10:$D$13,'Facturas y gastos'!$A$10:$A$13,A91))) -> 60.606919 | N91: =IF(J91="","",IF(SUMIFS('Facturas y gastos'!$D$10:$D$13,'Facturas y gastos'!$A$10:$A$13,A91)=0,"",J91*SUMIFS('Facturas y gastos'!$J$10:$J$13,'Facturas y gastos'!$A$10:$A$13,A91)/SUMIFS('Facturas y gastos'!$D$10:$D$13,'Facturas y gastos'!$A$10:$A$13,A91))) -> 0 | O91: =IF(J91="","",J91-K91+L91+M91+N91) -> 414.10828 | P91: =IF(OR(O91="",'Facturas y gastos'!$B$24="",'Facturas y gastos'!$B$45<>"OK",SUM($O$8:$O$657)=0),"",O91*'Facturas y gastos'!$B$43/SUM($O$8:$O$657)) | Q91: =IF(OR(O91="",'Facturas y gastos'!$B$5="",P91=""),"",O91*'Facturas y gastos'!$B$5+P91) | R91: =IF(OR(Q91="",F91="",F91=0),"",Q91/F91)
A92: A26TM06007-1 | B92: 85 | C92: PG216-1 | D92: Bandeja | E92: PCS | F92: 90 | G92: 5 | H92: 4.6 | I92: 413.73 | J92: =IF(OR(A92="",I92=""),"",IF(SUMIFS($I$8:$I$657,$A$8:$A$657,A92)=0,"",I92*SUMIFS('Facturas y gastos'!$D$10:$D$13,'Facturas y gastos'!$A$10:$A$13,A92)/SUMIFS($I$8:$I$657,$A$8:$A$657,A92))) -> 413.73 | K92: =IF(J92="","",IF(SUMIFS('Facturas y gastos'!$D$10:$D$13,'Facturas y gastos'!$A$10:$A$13,A92)=0,"",J92*SUMIFS('Facturas y gastos'!$G$10:$G$13,'Facturas y gastos'!$A$10:$A$13,A92)/SUMIFS('Facturas y gastos'!$D$10:$D$13,'Facturas y gastos'!$A$10:$A$13,A92))) -> 4.137322 | L92: =IF(J92="","",IF(SUMIFS('Facturas y gastos'!$D$10:$D$13,'Facturas y gastos'!$A$10:$A$13,A92)=0,"",J92*SUMIFS('Facturas y gastos'!$H$10:$H$13,'Facturas y gastos'!$A$10:$A$13,A92)/SUMIFS('Facturas y gastos'!$D$10:$D$13,'Facturas y gastos'!$A$10:$A$13,A92))) -> 12.411874 | M92: =IF(J92="","",IF(SUMIFS('Facturas y gastos'!$D$10:$D$13,'Facturas y gastos'!$A$10:$A$13,A92)=0,"",J92*SUMIFS('Facturas y gastos'!$I$10:$I$13,'Facturas y gastos'!$A$10:$A$13,A92)/SUMIFS('Facturas y gastos'!$D$10:$D$13,'Facturas y gastos'!$A$10:$A$13,A92))) -> 72.351618 | N92: =IF(J92="","",IF(SUMIFS('Facturas y gastos'!$D$10:$D$13,'Facturas y gastos'!$A$10:$A$13,A92)=0,"",J92*SUMIFS('Facturas y gastos'!$J$10:$J$13,'Facturas y gastos'!$A$10:$A$13,A92)/SUMIFS('Facturas y gastos'!$D$10:$D$13,'Facturas y gastos'!$A$10:$A$13,A92))) -> 0 | O92: =IF(J92="","",J92-K92+L92+M92+N92) -> 494.35617 | P92: =IF(OR(O92="",'Facturas y gastos'!$B$24="",'Facturas y gastos'!$B$45<>"OK",SUM($O$8:$O$657)=0),"",O92*'Facturas y gastos'!$B$43/SUM($O$8:$O$657)) | Q92: =IF(OR(O92="",'Facturas y gastos'!$B$5="",P92=""),"",O92*'Facturas y gastos'!$B$5+P92) | R92: =IF(OR(Q92="",F92="",F92=0),"",Q92/F92)
A93: A26TM06007-1 | B93: 86 | C93: PG217-1 | D93: Bandeja | E93: PCS | F93: 90 | G93: 5 | H93: 3.81 | I93: 342.54 | J93: =IF(OR(A93="",I93=""),"",IF(SUMIFS($I$8:$I$657,$A$8:$A$657,A93)=0,"",I93*SUMIFS('Facturas y gastos'!$D$10:$D$13,'Facturas y gastos'!$A$10:$A$13,A93)/SUMIFS($I$8:$I$657,$A$8:$A$657,A93))) -> 342.54 | K93: =IF(J93="","",IF(SUMIFS('Facturas y gastos'!$D$10:$D$13,'Facturas y gastos'!$A$10:$A$13,A93)=0,"",J93*SUMIFS('Facturas y gastos'!$G$10:$G$13,'Facturas y gastos'!$A$10:$A$13,A93)/SUMIFS('Facturas y gastos'!$D$10:$D$13,'Facturas y gastos'!$A$10:$A$13,A93))) -> 3.4254182 | L93: =IF(J93="","",IF(SUMIFS('Facturas y gastos'!$D$10:$D$13,'Facturas y gastos'!$A$10:$A$13,A93)=0,"",J93*SUMIFS('Facturas y gastos'!$H$10:$H$13,'Facturas y gastos'!$A$10:$A$13,A93)/SUMIFS('Facturas y gastos'!$D$10:$D$13,'Facturas y gastos'!$A$10:$A$13,A93))) -> 10.276179 | M93: =IF(J93="","",IF(SUMIFS('Facturas y gastos'!$D$10:$D$13,'Facturas y gastos'!$A$10:$A$13,A93)=0,"",J93*SUMIFS('Facturas y gastos'!$I$10:$I$13,'Facturas y gastos'!$A$10:$A$13,A93)/SUMIFS('Facturas y gastos'!$D$10:$D$13,'Facturas y gastos'!$A$10:$A$13,A93))) -> 59.902167 | N93: =IF(J93="","",IF(SUMIFS('Facturas y gastos'!$D$10:$D$13,'Facturas y gastos'!$A$10:$A$13,A93)=0,"",J93*SUMIFS('Facturas y gastos'!$J$10:$J$13,'Facturas y gastos'!$A$10:$A$13,A93)/SUMIFS('Facturas y gastos'!$D$10:$D$13,'Facturas y gastos'!$A$10:$A$13,A93))) -> 0 | O93: =IF(J93="","",J93-K93+L93+M93+N93) -> 409.29293 | P93: =IF(OR(O93="",'Facturas y gastos'!$B$24="",'Facturas y gastos'!$B$45<>"OK",SUM($O$8:$O$657)=0),"",O93*'Facturas y gastos'!$B$43/SUM($O$8:$O$657)) | Q93: =IF(OR(O93="",'Facturas y gastos'!$B$5="",P93=""),"",O93*'Facturas y gastos'!$B$5+P93) | R93: =IF(OR(Q93="",F93="",F93=0),"",Q93/F93)
A94: A26TM06007-1 | B94: 87 | C94: PG218-1 | D94: Bandeja | E94: PCS | F94: 500 | G94: 5 | H94: 0.76 | I94: 380 | J94: =IF(OR(A94="",I94=""),"",IF(SUMIFS($I$8:$I$657,$A$8:$A$657,A94)=0,"",I94*SUMIFS('Facturas y gastos'!$D$10:$D$13,'Facturas y gastos'!$A$10:$A$13,A94)/SUMIFS($I$8:$I$657,$A$8:$A$657,A94))) -> 380 | K94: =IF(J94="","",IF(SUMIFS('Facturas y gastos'!$D$10:$D$13,'Facturas y gastos'!$A$10:$A$13,A94)=0,"",J94*SUMIFS('Facturas y gastos'!$G$10:$G$13,'Facturas y gastos'!$A$10:$A$13,A94)/SUMIFS('Facturas y gastos'!$D$10:$D$13,'Facturas y gastos'!$A$10:$A$13,A94))) -> 3.8000202 | L94: =IF(J94="","",IF(SUMIFS('Facturas y gastos'!$D$10:$D$13,'Facturas y gastos'!$A$10:$A$13,A94)=0,"",J94*SUMIFS('Facturas y gastos'!$H$10:$H$13,'Facturas y gastos'!$A$10:$A$13,A94)/SUMIFS('Facturas y gastos'!$D$10:$D$13,'Facturas y gastos'!$A$10:$A$13,A94))) -> 11.399976 | M94: =IF(J94="","",IF(SUMIFS('Facturas y gastos'!$D$10:$D$13,'Facturas y gastos'!$A$10:$A$13,A94)=0,"",J94*SUMIFS('Facturas y gastos'!$I$10:$I$13,'Facturas y gastos'!$A$10:$A$13,A94)/SUMIFS('Facturas y gastos'!$D$10:$D$13,'Facturas y gastos'!$A$10:$A$13,A94))) -> 66.453037 | N94: =IF(J94="","",IF(SUMIFS('Facturas y gastos'!$D$10:$D$13,'Facturas y gastos'!$A$10:$A$13,A94)=0,"",J94*SUMIFS('Facturas y gastos'!$J$10:$J$13,'Facturas y gastos'!$A$10:$A$13,A94)/SUMIFS('Facturas y gastos'!$D$10:$D$13,'Facturas y gastos'!$A$10:$A$13,A94))) -> 0 | O94: =IF(J94="","",J94-K94+L94+M94+N94) -> 454.05299 | P94: =IF(OR(O94="",'Facturas y gastos'!$B$24="",'Facturas y gastos'!$B$45<>"OK",SUM($O$8:$O$657)=0),"",O94*'Facturas y gastos'!$B$43/SUM($O$8:$O$657)) | Q94: =IF(OR(O94="",'Facturas y gastos'!$B$5="",P94=""),"",O94*'Facturas y gastos'!$B$5+P94) | R94: =IF(OR(Q94="",F94="",F94=0),"",Q94/F94)
A95: A26TM06007-1 | B95: 88 | C95: PG218-2 | D95: Bandeja | E95: PCS | F95: 300 | G95: 5 | H95: 0.84 | I95: 252 | J95: =IF(OR(A95="",I95=""),"",IF(SUMIFS($I$8:$I$657,$A$8:$A$657,A95)=0,"",I95*SUMIFS('Facturas y gastos'!$D$10:$D$13,'Facturas y gastos'!$A$10:$A$13,A95)/SUMIFS($I$8:$I$657,$A$8:$A$657,A95))) -> 252 | K95: =IF(J95="","",IF(SUMIFS('Facturas y gastos'!$D$10:$D$13,'Facturas y gastos'!$A$10:$A$13,A95)=0,"",J95*SUMIFS('Facturas y gastos'!$G$10:$G$13,'Facturas y gastos'!$A$10:$A$13,A95)/SUMIFS('Facturas y gastos'!$D$10:$D$13,'Facturas y gastos'!$A$10:$A$13,A95))) -> 2.5200134 | L95: =IF(J95="","",IF(SUMIFS('Facturas y gastos'!$D$10:$D$13,'Facturas y gastos'!$A$10:$A$13,A95)=0,"",J95*SUMIFS('Facturas y gastos'!$H$10:$H$13,'Facturas y gastos'!$A$10:$A$13,A95)/SUMIFS('Facturas y gastos'!$D$10:$D$13,'Facturas y gastos'!$A$10:$A$13,A95))) -> 7.5599844 | M95: =IF(J95="","",IF(SUMIFS('Facturas y gastos'!$D$10:$D$13,'Facturas y gastos'!$A$10:$A$13,A95)=0,"",J95*SUMIFS('Facturas y gastos'!$I$10:$I$13,'Facturas y gastos'!$A$10:$A$13,A95)/SUMIFS('Facturas y gastos'!$D$10:$D$13,'Facturas y gastos'!$A$10:$A$13,A95))) -> 44.068856 | N95: =IF(J95="","",IF(SUMIFS('Facturas y gastos'!$D$10:$D$13,'Facturas y gastos'!$A$10:$A$13,A95)=0,"",J95*SUMIFS('Facturas y gastos'!$J$10:$J$13,'Facturas y gastos'!$A$10:$A$13,A95)/SUMIFS('Facturas y gastos'!$D$10:$D$13,'Facturas y gastos'!$A$10:$A$13,A95))) -> 0 | O95: =IF(J95="","",J95-K95+L95+M95+N95) -> 301.10883 | P95: =IF(OR(O95="",'Facturas y gastos'!$B$24="",'Facturas y gastos'!$B$45<>"OK",SUM($O$8:$O$657)=0),"",O95*'Facturas y gastos'!$B$43/SUM($O$8:$O$657)) | Q95: =IF(OR(O95="",'Facturas y gastos'!$B$5="",P95=""),"",O95*'Facturas y gastos'!$B$5+P95) | R95: =IF(OR(Q95="",F95="",F95=0),"",Q95/F95)
A96: A26TM06007-1 | B96: 89 | C96: PG218-3 | D96: Bandeja | E96: PCS | F96: 200 | G96: 5 | H96: 1.26 | I96: 252 | J96: =IF(OR(A96="",I96=""),"",IF(SUMIFS($I$8:$I$657,$A$8:$A$657,A96)=0,"",I96*SUMIFS('Facturas y gastos'!$D$10:$D$13,'Facturas y gastos'!$A$10:$A$13,A96)/SUMIFS($I$8:$I$657,$A$8:$A$657,A96))) -> 252 | K96: =IF(J96="","",IF(SUMIFS('Facturas y gastos'!$D$10:$D$13,'Facturas y gastos'!$A$10:$A$13,A96)=0,"",J96*SUMIFS('Facturas y gastos'!$G$10:$G$13,'Facturas y gastos'!$A$10:$A$13,A96)/SUMIFS('Facturas y gastos'!$D$10:$D$13,'Facturas y gastos'!$A$10:$A$13,A96))) -> 2.5200134 | L96: =IF(J96="","",IF(SUMIFS('Facturas y gastos'!$D$10:$D$13,'Facturas y gastos'!$A$10:$A$13,A96)=0,"",J96*SUMIFS('Facturas y gastos'!$H$10:$H$13,'Facturas y gastos'!$A$10:$A$13,A96)/SUMIFS('Facturas y gastos'!$D$10:$D$13,'Facturas y gastos'!$A$10:$A$13,A96))) -> 7.5599844 | M96: =IF(J96="","",IF(SUMIFS('Facturas y gastos'!$D$10:$D$13,'Facturas y gastos'!$A$10:$A$13,A96)=0,"",J96*SUMIFS('Facturas y gastos'!$I$10:$I$13,'Facturas y gastos'!$A$10:$A$13,A96)/SUMIFS('Facturas y gastos'!$D$10:$D$13,'Facturas y gastos'!$A$10:$A$13,A96))) -> 44.068856 | N96: =IF(J96="","",IF(SUMIFS('Facturas y gastos'!$D$10:$D$13,'Facturas y gastos'!$A$10:$A$13,A96)=0,"",J96*SUMIFS('Facturas y gastos'!$J$10:$J$13,'Facturas y gastos'!$A$10:$A$13,A96)/SUMIFS('Facturas y gastos'!$D$10:$D$13,'Facturas y gastos'!$A$10:$A$13,A96))) -> 0 | O96: =IF(J96="","",J96-K96+L96+M96+N96) -> 301.10883 | P96: =IF(OR(O96="",'Facturas y gastos'!$B$24="",'Facturas y gastos'!$B$45<>"OK",SUM($O$8:$O$657)=0),"",O96*'Facturas y gastos'!$B$43/SUM($O$8:$O$657)) | Q96: =IF(OR(O96="",'Facturas y gastos'!$B$5="",P96=""),"",O96*'Facturas y gastos'!$B$5+P96) | R96: =IF(OR(Q96="",F96="",F96=0),"",Q96/F96)
A97: A26TM06007-1 | B97: 90 | C97: PG219-1 | D97: Bandeja | E97: PCS | F97: 360 | G97: 6 | H97: 1.43 | I97: 514.8 | J97: =IF(OR(A97="",I97=""),"",IF(SUMIFS($I$8:$I$657,$A$8:$A$657,A97)=0,"",I97*SUMIFS('Facturas y gastos'!$D$10:$D$13,'Facturas y gastos'!$A$10:$A$13,A97)/SUMIFS($I$8:$I$657,$A$8:$A$657,A97))) -> 514.8 | K97: =IF(J97="","",IF(SUMIFS('Facturas y gastos'!$D$10:$D$13,'Facturas y gastos'!$A$10:$A$13,A97)=0,"",J97*SUMIFS('Facturas y gastos'!$G$10:$G$13,'Facturas y gastos'!$A$10:$A$13,A97)/SUMIFS('Facturas y gastos'!$D$10:$D$13,'Facturas y gastos'!$A$10:$A$13,A97))) -> 5.1480273 | L97: =IF(J97="","",IF(SUMIFS('Facturas y gastos'!$D$10:$D$13,'Facturas y gastos'!$A$10:$A$13,A97)=0,"",J97*SUMIFS('Facturas y gastos'!$H$10:$H$13,'Facturas y gastos'!$A$10:$A$13,A97)/SUMIFS('Facturas y gastos'!$D$10:$D$13,'Facturas y gastos'!$A$10:$A$13,A97))) -> 15.443968 | M97: =IF(J97="","",IF(SUMIFS('Facturas y gastos'!$D$10:$D$13,'Facturas y gastos'!$A$10:$A$13,A97)=0,"",J97*SUMIFS('Facturas y gastos'!$I$10:$I$13,'Facturas y gastos'!$A$10:$A$13,A97)/SUMIFS('Facturas y gastos'!$D$10:$D$13,'Facturas y gastos'!$A$10:$A$13,A97))) -> 90.026378 | N97: =IF(J97="","",IF(SUMIFS('Facturas y gastos'!$D$10:$D$13,'Facturas y gastos'!$A$10:$A$13,A97)=0,"",J97*SUMIFS('Facturas y gastos'!$J$10:$J$13,'Facturas y gastos'!$A$10:$A$13,A97)/SUMIFS('Facturas y gastos'!$D$10:$D$13,'Facturas y gastos'!$A$10:$A$13,A97))) -> 0 | O97: =IF(J97="","",J97-K97+L97+M97+N97) -> 615.12232 | P97: =IF(OR(O97="",'Facturas y gastos'!$B$24="",'Facturas y gastos'!$B$45<>"OK",SUM($O$8:$O$657)=0),"",O97*'Facturas y gastos'!$B$43/SUM($O$8:$O$657)) | Q97: =IF(OR(O97="",'Facturas y gastos'!$B$5="",P97=""),"",O97*'Facturas y gastos'!$B$5+P97) | R97: =IF(OR(Q97="",F97="",F97=0),"",Q97/F97)
